Workbook

Sheet Sheet1
A1: Lx | B1: 1000 | H1: =MATCH(E2, Table26!$B$5:$I$5, 1) -> 8 | I1: Alpha x (-ve) | J1: Alpha x (+ve)
A2: Ly | B2: 3173 | D2: Ly/Lx Ratio | E2: =B2/B1 -> 3.173 | H2: {=INDEX(Table26!$B$5:$I$5, H1)} -> 2 | I2: {=INDEX(Table26!$B$6:$I$14, B28, H1)} -> 0.068 | J2: {=INDEX(Table26!$B$18:$I$26, B28, H1)} -> 0.052
A3: Fck | B3: 20 | D3: Slab Type | E3: =IF(E2 < 2, "Two-Way Slab", "One-Way Slab") -> One-Way Slab | H3: {=IF(H1=8, H2, INDEX(Table26!$B$5:$I$5, H1+1))} -> 2 | I3: {=IF(H1=8, I2, INDEX(Table26!$B$6:$I$14, B28, H1+1))} -> 0.068 | J3: {=IF(H1=8, J2, INDEX(Table26!$B$18:$I$26, B28, H1+1))} -> 0.052
A4: Fy | B4: 415 | H4: =E2 -> 3.173 | I4: =I2 + IFERROR((E2-H2)*(I3-I2)/(H3-H2), 0) -> 0.068 | J4: =J2 + IFERROR((E2-H2)*(J3-J2)/(H3-H2), 0) -> 0.052
A5: Assume:
A6: Overall Depth D (mm) | B6: 100
A7: Clear Cover (mm) | B7: 15
A8: Bar Diameter (mm) | B8: 6
A9: Imposed Load (KN/m²) | B9: 2
A10: Floor Finish (KN/m²) | B10: 1
A13: Effective Depth - Short (dx): | B13: =B6-B7-(B8/2) -> 82
A14: Effective Depth - long (dy): | B14: =B6-B7-B8-(B8/2) -> 76
A15: Self Weight (KN/m²) | B15: =25*(B6/1000) -> 2.5
A16: Factored Load (W) | B16: =1.5*(B9+B10+B15) -> 8.25
B20: Maximum Bending Moment (Mu) in (KN-m) | C20: =MAX(E29:E32) -> 0.561
B22: Ast (Shorter Span) | C22: =(0.5*B3/B4)*(1-SQRT(1-(4.6*C20*10^6)/(B3*1000*B13^2)))*1000*B13 -> 19.050105
B23: Ast Limit | C23: =(0.12/100)*1000*B6 -> 120
B24: Final Required Ast | C24: =MAX(C22, C23) -> 120
A28: Case Number | B28: 2
A29: Alpha x (-ve) | B29: =I4 -> 0.068 | D29: (Mux -ve): | E29: =B29 * B16 * (B1/1000)^2 -> 0.561
A30: Alpha x (+ve) | B30: =J4 -> 0.052 | D30: (Mux +ve): | E30: =B30 * B16 * (B1/1000)^2 -> 0.429
A31: Alpha y (-ve) | B31: {=INDEX(Table26!$B$31:$B$39, B28)} -> 0.037 | D31: (Muy -ve): | E31: =B31 * B16 * (B1/1000)^2 -> 0.30525
A32: Alpha y (+ve) | B32: {=INDEX(Table26!$C$31:$C$39, B28)} -> 0.028 | D32: (Muy +ve): | E32: =B32 * B16 * (B1/1000)^2 -> 0.231
D34: Check For Depth
D35: d required (mm) | E35: =SQRT((C20 * 10^6) / (0.1336 * 1000 * B3)) -> 14.489827
D36: STATUS: | E36: =IF(E35 < B6, "SAFE IN BENDING", "UNSAFE - INCREASE OVERALL DEPTH") -> SAFE IN BENDING
A39: SHORTER SPAN REINFORCEMENT (Ast,x) | D39: LONGER SPAN REINFORCEMENT (Ast,x)
A40: +ve Reinforcement for shorter span: | D40: +ve Reinforcement for Longer span:
A41: Calculated Ast (mm²) | B41: =(0.5 * B3 / B4) * (1 - SQRT(1 - ((4.6 * E30 * 10^6) / (B3 * 1000 * B13^2)))) * 1000 * B13 -> 14.551081 | D41: Calculated Ast (mm²) | E41: =(0.5 * B3 / B4) * (1 - SQRT(1 - ((4.6 * E32 * 10^6) / (B3 * 1000 * B14^2)))) * 1000 * B14 -> 8.4420962
A42: Ast Limit (mm²) | B42: =1.2 * B6 -> 120 | D42: Ast Limit (mm²) | E42: =1.2 * B6 -> 120
A43: FINAL MINIMUM Ast,x | B43: =MAX(B41, B42) -> 120 | D43: FINAL MINIMUM Ast,x | E43: =MAX(E41, E42) -> 120
A44: Spacing | D44: Spacing
A45: S= | B45: =3*B13 -> 246 | D45: S= | E45: =3*B14 -> 228
A47: SHORTER SPAN REINFORCEMENT (Ast,x) | D47: LONGER SPAN REINFORCEMENT (Ast,x)
A48: -ve Reinforcement for shorter span: | D48: -ve Reinforcement for Longer span:
A49: Calculated Ast (mm²) | B49: =(0.5 * B3 / B4) * (1 - SQRT(1 - ((4.6 * E29 * 10^6) / (B3 * 1000 * B13^2)))) * 1000 * B13 -> 19.050105 | D49: Calculated Ast (mm²) | E49: =(0.5 * B3 / B4) * (1 - SQRT(1 - ((4.6 * E31 * 10^6) / (B3 * 1000 * B14^2)))) * 1000 * B14 -> 11.163943
A50: Ast Limit (mm²) | B50: =1.2 * B6 -> 120 | D50: Ast Limit (mm²) | E50: =1.2 * B6 -> 120
A51: FINAL MINIMUM Ast,x | B51: =MAX(B49, B50) -> 120 | D51: FINAL MINIMUM Ast,x | E51: =MAX(E49, E50) -> 120
A52: Spacing | D52: Spacing
A53: S= | B53: =3*B13 -> 246 | D53: S= | E53: =3*B14 -> 228
...

Sheet Table26
A1: Table 26
A2: Bending Moment Coefficients for Rectangular Panels Supported on Four Sides with Provision for Torsion at Corners
A4: Negetive Alpha(x) Values
A5: Case No. | B5: 1 | C5: 1.1 | D5: 1.2 | E5: 1.3 | F5: 1.4 | G5: 1.5 | H5: 1.75 | I5: 2
A6: 1 | B6: 0.032 | C6: 0.037 | D6: 0.043 | E6: 0.047 | F6: 0.051 | G6: 0.053 | H6: 0.06 | I6: 0.065
A7: 2 | B7: 0.037 | C7: 0.043 | D7: 0.048 | E7: 0.051 | F7: 0.055 | G7: 0.057 | H7: 0.064 | I7: 0.068
A8: 3 | B8: 0.037 | C8: 0.044 | D8: 0.052 | E8: 0.057 | F8: 0.063 | G8: 0.067 | H8: 0.077 | I8: 0.085
A9: 4 | B9: 0.047 | C9: 0.053 | D9: 0.06 | E9: 0.065 | F9: 0.071 | G9: 0.075 | H9: 0.084 | I9: 0.091
A10: 5 | B10: 0.045 | C10: 0.049 | D10: 0.052 | E10: 0.056 | F10: 0.059 | G10: 0.06 | H10: 0.065 | I10: 0.069
A11: 6
A12: 7 | B12: 0.057 | C12: 0.064 | D12: 0.071 | E12: 0.076 | F12: 0.08 | G12: 0.084 | H12: 0.091 | I12: 0.097
A13: 8
A14: 9
A16: Positive Alpha(x) Values
A17: Case No. | B17: 1 | C17: 1.1 | D17: 1.2 | E17: 1.3 | F17: 1.4 | G17: 1.5 | H17: 1.75 | I17: 2
A18: 1 | B18: 0.024 | C18: 0.028 | D18: 0.032 | E18: 0.036 | F18: 0.039 | G18: 0.041 | H18: 0.045 | I18: 0.049
A19: 2 | B19: 0.028 | C19: 0.032 | D19: 0.036 | E19: 0.039 | F19: 0.041 | G19: 0.044 | H19: 0.048 | I19: 0.052
A20: 3 | B20: 0.028 | C20: 0.033 | D20: 0.039 | E20: 0.044 | F20: 0.047 | G20: 0.051 | H20: 0.059 | I20: 0.065
A21: 4 | B21: 0.035 | C21: 0.04 | D21: 0.045 | E21: 0.049 | F21: 0.053 | G21: 0.056 | H21: 0.063 | I21: 0.069
A22: 5 | B22: 0.035 | C22: 0.037 | D22: 0.04 | E22: 0.043 | F22: 0.044 | G22: 0.045 | H22: 0.049 | I22: 0.052
A23: 6 | B23: 0.035 | C23: 0.043 | D23: 0.051 | E23: 0.057 | F23: 0.063 | G23: 0.068 | H23: 0.08 | I23: 0.088
A24: 7 | B24: 0.043 | C24: 0.048 | D24: 0.053 | E24: 0.057 | F24: 0.06 | G24: 0.064 | H24: 0.069 | I24: 0.073
A25: 8 | B25: 0.043 | C25: 0.051 | D25: 0.059 | E25: 0.065 | F25: 0.071 | G25: 0.076 | H25: 0.087 | I25: 0.096
A26: 9 | B26: 0.056 | C26: 0.064 | D26: 0.072 | E26: 0.079 | F26: 0.085 | G26: 0.089 | H26: 0.1 | I26: 0.107
A30: Case No. | B30: Negative Alpha(y) | C30: Positive Alpha(y)
A31: 1 | B31: 0.032 | C31: 0.024
A32: 2 | B32: 0.037 | C32: 0.028
A33: 3 | B33: 0.037 | C33: 0.028
A34: 4 | B34: 0.047 | C34: 0.035
A35: 5 | C35: 0.035
A36: 6 | B36: 0.045 | C36: 0.035
A37: 7 | C37: 0.043
A38: 8 | B38: 0.057 | C38: 0.043
A39: 9 | C39: 0.056
